<?xml version="1.0" encoding="utf-8"?>
<!-- This URDF was automatically created by SolidWorks to URDF Exporter! Originally created by Stephen Brawner (brawner@gmail.com) 
     Commit Version: 1.5.1-0-g916b5db  Build Version: 1.5.7152.31018
     For more information, please see http://wiki.ros.org/sw_urdf_exporter -->
<robot
  name="vanderbot">
  <link
    name="base_link">
    <inertial>
      <origin
        xyz="0.0042869 0.010394 -0.00046682"
        rpy="0 0 0" />
      <mass
        value="0.80794" />
      <inertia
        ixx="0.0017182"
        ixy="3.2535E-07"
        ixz="6.6866E-06"
        iyy="0.0034685"
        iyz="8.0182E-08"
        izz="0.0017776" />
    </inertial>
    <visual>
      <origin
        xyz="0 0 0"
        rpy="0 0 0" />
      <geometry>
        <mesh
          filename="package://vanderbot/meshes/base_link.STL" />
      </geometry>
      <material
        name="">
        <color
          rgba="0.89804 0.91765 0.92941 1" />
      </material>
    </visual>
    <collision>
      <origin
        xyz="0 0 0"
        rpy="0 0 0" />
      <geometry>
        <mesh
          filename="package://vanderbot/meshes/base_link.STL" />
      </geometry>
    </collision>
  </link>
  <link
    name="link_1">
    <inertial>
      <origin
        xyz="-0.00070352 -0.061274 0.017423"
        rpy="0 0 0" />
      <mass
        value="0.5361" />
      <inertia
        ixx="0.00032702"
        ixy="-6.6866E-06"
        ixz="-8.0182E-08"
        iyy="0.00025426"
        iyz="2.3847E-06"
        izz="0.00045888" />
    </inertial>
    <visual>
      <origin
        xyz="0 0 0"
        rpy="0 0 0" />
      <geometry>
        <mesh
          filename="package://vanderbot/meshes/link_1.STL" />
      </geometry>
      <material
        name="">
        <color
          rgba="0.89804 0.91765 0.92941 1" />
      </material>
    </visual>
    <collision>
      <origin
        xyz="0 0 0"
        rpy="0 0 0" />
      <geometry>
        <mesh
          filename="package://vanderbot/meshes/link_1.STL" />
      </geometry>
    </collision>
  </link>
  <joint
    name="base"
    type="continuous">
    <origin
      xyz="0 0.050345 0"
      rpy="0 0 3.1416" />
    <parent
      link="base_link" />
    <child
      link="link_1" />
    <axis
      xyz="0 -1 0" />
  </joint>
  <link
    name="link_2">
    <inertial>
      <origin
        xyz="0.23768 -0.0037506 -0.012429"
        rpy="0 0 0" />
      <mass
        value="0.74175" />
      <inertia
        ixx="0.00026132"
        ixy="1.0362E-05"
        ixz="-1.316E-07"
        iyy="0.0019116"
        iyz="-1.7517E-07"
        izz="0.0021139" />
    </inertial>
    <visual>
      <origin
        xyz="0 0 0"
        rpy="0 0 0" />
      <geometry>
        <mesh
          filename="package://vanderbot/meshes/link_2.STL" />
      </geometry>
      <material
        name="">
        <color
          rgba="0.89804 0.91765 0.92941 1" />
      </material>
    </visual>
    <collision>
      <origin
        xyz="0 0 0"
        rpy="0 0 0" />
      <geometry>
        <mesh
          filename="package://vanderbot/meshes/link_2.STL" />
      </geometry>
    </collision>
  </link>
  <joint
    name="shoulder"
    type="continuous">
    <origin
      xyz="0 -0.08053 -0.013525"
      rpy="0 0 0" />
    <parent
      link="link_1" />
    <child
      link="link_2" />
    <axis
      xyz="0 0 -1" />
  </joint>
  <link
    name="link_3">
    <inertial>
      <origin
        xyz="0.0035901 -0.0052836 -0.37788"
        rpy="0 0 0" />
      <mass
        value="0.44825" />
      <inertia
        ixx="0.0039577"
        ixy="-5.1426E-08"
        ixz="7.3709E-08"
        iyy="0.0038647"
        iyz="5.1281E-06"
        izz="0.00013762" />
    </inertial>
    <visual>
      <origin
        xyz="0 0 0"
        rpy="0 0 0" />
      <geometry>
        <mesh
          filename="package://vanderbot/meshes/link_3.STL" />
      </geometry>
      <material
        name="">
        <color
          rgba="0.89804 0.91765 0.92941 1" />
      </material>
    </visual>
    <collision>
      <origin
        xyz="0 0 0"
        rpy="0 0 0" />
      <geometry>
        <mesh
          filename="package://vanderbot/meshes/link_3.STL" />
      </geometry>
    </collision>
  </link>
  <joint
    name="elbow"
    type="continuous">
    <origin
      xyz="0.4666 0 0.04505"
      rpy="3.1416 -1.5708 0" />
    <parent
      link="link_2" />
    <child
      link="link_3" />
    <axis
      xyz="1 0 0" />
  </joint>
  <link
    name="link_4">
    <inertial>
      <origin
        xyz="0.0011857 0.044307 -0.026463"
        rpy="0 0 0" />
      <mass
        value="0.23876" />
      <inertia
        ixx="0.0001498"
        ixy="-7.3709E-08"
        ixz="-4.5751E-06"
        iyy="0.00020652"
        iyz="1.7037E-05"
        izz="0.00011785" />
    </inertial>
    <visual>
      <origin
        xyz="0 0 0"
        rpy="0 0 0" />
      <geometry>
        <mesh
          filename="package://vanderbot/meshes/link_4.STL" />
      </geometry>
      <material
        name="">
        <color
          rgba="0.29804 0.29804 0.29804 1" />
      </material>
    </visual>
    <collision>
      <origin
        xyz="0 0 0"
        rpy="0 0 0" />
      <geometry>
        <mesh
          filename="package://vanderbot/meshes/link_4.STL" />
      </geometry>
    </collision>
  </link>
  <joint
    name="wrist"
    type="continuous">
    <origin
      xyz="-0.031045 0 -0.5556"
      rpy="0 1.5708 0" />
    <parent
      link="link_3" />
    <child
      link="link_4" />
    <axis
      xyz="0 0 1" />
  </joint>
  <link
    name="link_5">
    <inertial>
      <origin
        xyz="0.00040185 0.036541 -0.014765"
        rpy="0 0 0" />
      <mass
        value="0.079101" />
      <inertia
        ixx="3.215E-05"
        ixy="-5.5297E-08"
        ixz="-1.173E-10"
        iyy="2.1405E-05"
        iyz="6.7911E-07"
        izz="2.6463E-05" />
    </inertial>
    <visual>
      <origin
        xyz="0 0 0"
        rpy="0 0 0" />
      <geometry>
        <mesh
          filename="package://vanderbot/meshes/link_5.STL" />
      </geometry>
      <material
        name="">
        <color
          rgba="0.75294 0.75294 0.75294 1" />
      </material>
    </visual>
    <collision>
      <origin
        xyz="0 0 0"
        rpy="0 0 0" />
      <geometry>
        <mesh
          filename="package://vanderbot/meshes/link_5.STL" />
      </geometry>
    </collision>
  </link>
  <joint
    name="twist"
    type="continuous">
    <origin
      xyz="0 0.07105 -0.04353"
      rpy="0 0 0" />
    <parent
      link="link_4" />
    <child
      link="link_5" />
    <axis
      xyz="0 1 0" />
  </joint>
  <link
    name="link_6">
    <inertial>
      <origin
        xyz="-0.64244 0.072634 0.1515"
        rpy="0 0 0" />
      <mass
        value="62.759" />
      <inertia
        ixx="11.425"
        ixy="0.0060311"
        ixz="-0.003515"
        iyy="14.896"
        iyz="-0.0014531"
        izz="3.6364" />
    </inertial>
    <visual>
      <origin
        xyz="0 0 0"
        rpy="0 0 0" />
      <geometry>
        <mesh
          filename="package://vanderbot/meshes/link_6.STL" />
      </geometry>
      <material
        name="">
        <color
          rgba="1 1 1 1" />
      </material>
    </visual>
    <collision>
      <origin
        xyz="0 0 0"
        rpy="0 0 0" />
      <geometry>
        <mesh
          filename="package://vanderbot/meshes/link_6.STL" />
      </geometry>
    </collision>
  </link>
  <joint
    name="tip"
    type="fixed">
    <origin
      xyz="0 0.00455 -0.10875"
      rpy="0 0 0" />
    <parent
      link="link_5" />
    <child
      link="link_6" />
    <axis
      xyz="0 0 0" />
  </joint>
</robot>